<!--
/**
 * Dev Series
 * promises
 * Copyright (C) 2021 Thorsten Suckow-Homberg https://github.com/DeveloperSeries
 *
 * Permission is hereby granted, free of charge, to any person
 * obtaining a copy of this software and associated documentation
 * files (the "Software"), to deal in the Software without restriction,
 * including without limitation the rights to use, copy, modify, merge,
 * publish, distribute, sublicense, and/or sell copies of the Software,
 * and to permit persons to whom the Software is furnished to do so,
 * subject to the following conditions:
 *
 * The above copyright notice and this permission notice shall be included
 * in all copies or substantial portions of the Software.
 *
 * THE SOFTWARE IS PROVIDED "AS IS", WITHOUT WARRANTY OF ANY KIND,
 * EXPRESS OR IMPLIED, INCLUDING BUT NOT LIMITED TO THE WARRANTIES
 * OF MERCHANTABILITY, FITNESS FOR A PARTICULAR PURPOSE AND NONINFRINGEMENT.
 * IN NO EVENT SHALL THE AUTHORS OR COPYRIGHT HOLDERS BE LIABLE FOR ANY CLAIM,
 * DAMAGES OR OTHER LIABILITY, WHETHER IN AN ACTION OF CONTRACT, TORT OR
 * OTHERWISE, ARISING FROM, OUT OF OR IN CONNECTION WITH THE SOFTWARE OR THE
 * USE OR OTHER DEALINGS IN THE SOFTWARE.
 */
-->
<!doctype html>
<html>
<head>

    <script type="module" src="./src/Loader.js"></script>


    <script type="module">

        import Loader from "./src/Loader.js";

        const loader = new Loader(),
              filename = "./resources/somefile.txt";

        // +----------------------------------------------------------
        // | Successful file loading
        // +----------------------------------------------------------
        /**
         * Case S.1 (ASYNC/AWAIT)
         * ---------------------------------------------------
         * We are using "await" to make sure we are properly waiting for the Promise to resolve.
         * Since "await" is only allowed in async methods, we need to wrap the call to load()
         * in an async method.
         */
        (async () => {
            try {
                let responseText = await loader.load(filename);
                console.log(filename, " was loaded. Loaded contents: ", responseText);
            } catch (e) {
                console.log("Unexpected! If an error is thrown here, something is broken.", e);
            }
        })();

        /**
         * Case S.2 (THENABLE)
         * ---------------------------------------------------
         * We are using "then()" to chain method calls with the Promise object returned by load().
         * As soon as the Promise is resolved, the method named "resolve" is called.
         * This is what we previously often used as a callback for a (succesful) asynchronous operation,
         * but a lot of wiring and configuration is already done by the promise itself before this
         * method gets called with the result of the operation.
         */
        let resolve = (responseText) => console.log(filename, " was loaded. Loaded contents: ", responseText);
        loader.load(filename).then(
            resolve,
            // this method should never been called in our reference implementation
            (e) => console.log("Unexpected! If an error is thrown here, something is broken.", e)
        );

        // +----------------------------------------------------------
        // | Proper exception handling
        // +----------------------------------------------------------
        /**
         * Case E.1 (Exception - argument missing / ASYNC/AWAIT)
         * ---------------------------------------------------
         * Although the location where the exception is thrown is not part of the Promise itself,
         * the "async" keyword makes sure that the "load()"-method returns a Promise.
         * We have to make sure we treat the returned Promise the right way, otherwise we
         * won't be able to do proper exception handling
         */
        (async () => {
            try {
                let ret = await loader.load();
            } catch (e) {
                console.log("Expected exception thrown (missing url argument):", e.message);
            }
        })();

        /**
         * Case E.2 (Exception - argument missing / THENABLE)
         * ------------------------------------------------
         * Since async methods return a Promise object if the operation's result was
         * not handled by the "await" keyword, we can use then() on the returned Promise,
         * no matter if it was successfully resolved or due to an error rejected
         */
        loader.load().then(() => {}, (e) => console.log("Expected exception thrown (missing url argument):", e.message));

        /**
         * Case E.3 (Exception - argument missing / no proper handler used)
         * ------------------------------------------------
         * In this example we're neither using "await" nor then().
         * The exception cannot be caught by our naive implementation and bubbles up to the console,
         * although we're using try/catch
         */
        try {
            loader.load();
        } catch (e) {
            // this code will not be reached
            console.log("if you can read this, something is seriously broken", e);
        }

        // +----------------------------------------------------------
        // | Dos and Donts
        // +----------------------------------------------------------
        /**
         * Case D.1 (Wrong assumption of the return value of load())
         * ---------------------------------------------------------
         * Reading the load()-method a developer unfamiliar with async/await
         * might assume that the value returned by this method is already the responseText
         * of the XmlHttpRequest. async/await is already used in there,
         * so JavaScript should somehow be able to take care of the asynchronous process at this
         * exact same location, right? Wrong! This is not how asynchronous method calls work.
         * General rule of thumb - if you come across a method tagged with the async keyword,
         * treat the return value like a Promise, no matter what!
         */
        let responseText = loader.load(filename);
        console.log("This will not console log the contents of the file - instead, you'll get a Promise!", responseText);

        /**
         * Case D.2 (Correct treatment of return values of async methods)
         * --------------------------------------------------------------
         * An async method will ALWAYS return a Promise, even if you have implemented no promise in the async method
         * itself and simply want to return a simple datatype, like a string.
         * JavaScript will automatically wrap the return value in a Promise that is already resolve.
         * (i.e. Promise.resolve([somevalue]))
         */
        const promiseAutoResolver = async () => {
            return "1";
        };

        console.log(
            "The return value of promiseAutoResolver is a Promise that has been resolved",
             (promiseAutoResolver() instanceof Promise) === true
        );
        promiseAutoResolver().then((result) => console.log("...and it resolves with the value:", result));

        /**
         * Case D.3 (Correct treatment of exceptions of async methods)
         * --------------------------------------------------------------
         * Likewise, an async method will ALWAYS wrap an uncaught exception in a Promise
         * which's state will be set to "rejected". So, instead of being able to catch an exception
         * that was thrown by the promise, you will need to properly implement
         * method calls to get to the error itself.
         * JavaScript will automatically wrap an uncaught/untreated exception thrown by a Promise
         * in a Promise that was rejected, i.e. Promise.reject([someerror])
         */
        const promiseAutoRejecter = async () => {
            throw Error("you got rejected!");
        };
        try {
            console.log(
                "The return value of promiseAutoRejecter is a Promise that has been rejected",
                (promiseAutoRejecter() instanceof Promise) === true,
                ", but we need to properly catch it"
            );
        } catch (e) {
            // we won't reach the catch-block
        }
        // that's better!
        promiseAutoRejecter().then(() => {}, (error) => console.log("...and it rejects with the following error:", error));
    </script>


</head>




<body>

<div>Please open your browser's console for debugging output.</div>

</body>


</html>